<?xml version="1.0"?>
<robot xmlns:xacro="http://www.ros.org/wiki/xacro">

  <!-- Import all Gazebo-customization elements, including Gazebo colors -->
  <xacro:include filename="$(find iiwa_description)/urdf/iiwa.gazebo.xacro" />
  <!-- Import Transmissions -->
  <xacro:include filename="$(find iiwa_description)/urdf/iiwa.transmission.xacro" />
  <!-- Include Utilities -->
  <xacro:include filename="$(find iiwa_description)/urdf/utilities.xacro" />

  <!-- some constants -->
  <xacro:property name="safety_controller_k_pos" value="100" />
  <xacro:property name="safety_controller_k_vel" value="2" />
  <xacro:property name="max_effort" value="300"/>
  <xacro:property name="max_velocity" value="10"/>
  
  
  <xacro:property name="damping_factor" value="0.0"/>

   <xacro:property name="d0" value="${damping_factor*0.241499}"/>
   <xacro:property name="d1" value="${damping_factor*0.373279}"/>
   <xacro:property name="d2" value="${damping_factor*0.110253}"/>
   <xacro:property name="d3" value="${damping_factor*0.100000}"/>
   <xacro:property name="d4" value="${damping_factor*0.100000}"/>
   <xacro:property name="d5" value="${damping_factor*0.124842}"/>
   <xacro:property name="d6" value="${damping_factor*0.100000}"/>

   <xacro:property name="friction_factor" value="0.0"/>

   <xacro:property name="f0" value="${friction_factor*0.319088	*	1.0 }"/>
   <xacro:property name="f1" value="${friction_factor*0.181301}"/>
   <xacro:property name="f2" value="${friction_factor*0.073019}"/>
   <xacro:property name="f3" value="${friction_factor*0.176713}"/>
   <xacro:property name="f4" value="${friction_factor*0.034631	*	1.0 }"/>
   <xacro:property name="f5" value="${friction_factor*0.133913}"/>
   <xacro:property name="f6" value="${friction_factor*0.087096 	*	1.0 }"/>

  <xacro:macro name="iiwa14" params="parent hardware_interface robot_name *origin">

    <!--joint between {parent} and link_0-->
    <joint name="${parent}_joint" type="fixed">
      <xacro:insert_block name="origin"/>
      <parent link="${parent}"/>
      <child link="link_0"/>
    </joint>

    <link name="link_0">
      <inertial>
        <origin xyz="-0.1 0 0.07" rpy="0 0 0"/>
        <mass value="5"/>
        <inertia ixx="0.05"  ixy="0"  ixz="0" iyy="0.06" iyz="0" izz="0.03" />
      </inertial>

      <visual>
        <origin xyz="0 0 0" rpy="0 0 0"/>
        <geometry>
          <mesh filename="package://iiwa_description/meshes/iiwa14/visual/link_0.stl"/>
        </geometry>
        <material name="Grey"/>
      </visual>

      <collision>
        <origin xyz="0 0 0" rpy="0 0 0"/>
        <geometry>
          <mesh filename="package://iiwa_description/meshes/iiwa14/collision/link_0.stl"/>
        </geometry>
        <material name="Grey"/>
      </collision>

      <self_collision_checking>
        <origin xyz="0 0 0" rpy="0 0 0"/>
        <geometry>
          <capsule radius="0.15" length="0.25"/>
        </geometry>
      </self_collision_checking>

    </link>

    <!-- joint between link_0 and link_1 -->
    <joint name="joint_0" type="revolute">
      <parent link="link_0"/>
      <child link="link_1"/>
      <origin xyz="0 0 0.1575" rpy="0 0 ${PI}"/>
      <axis xyz="0 0 1"/>
      <limit lower="${-170 * PI / 180}" upper="${170 * PI / 180}"
             effort="${max_effort}" velocity="${max_velocity}" />
         <safety_controller soft_lower_limit="${-168 * PI / 180}"
           soft_upper_limit="${168 * PI / 180}"
           k_position="${safety_controller_k_pos}"
           k_velocity="${safety_controller_k_vel}"/>
      <dynamics damping="${d0}" friction="${f0}"/>
    </joint>

    <link name="link_1">
      <inertial>
        <origin xyz="-0.0035 0.001602 ${-0.031387+0.2025}" rpy="0 0 0"/>
        <mass value="3.947808"/>
        <inertia ixx="0.004554"  ixy="0"  ixz="0" iyy="0.004542" iyz="0" izz="0.000289" />
      </inertial>

      <visual>
        <origin xyz="0 0 0" rpy="0 0 ${PI}"/>
        <geometry>
          <mesh filename="package://iiwa_description/meshes/iiwa14/visual/link_1.stl"/>
        </geometry>
        <material name="Orange"/>
      </visual>

      <collision>
        <origin xyz="0 0 0" rpy="0 0 ${PI}"/>
        <geometry>
          <mesh filename="package://iiwa_description/meshes/iiwa14/collision/link_1.stl"/>
        </geometry>
        <material name="Orange"/>
      </collision>
    </link>

    <!-- joint between link_1 and link_2 -->
    <joint name="joint_1" type="revolute">
      <parent link="link_1"/>
      <child link="link_2"/>
      <origin xyz="0 0 0.2025" rpy="${PI / 2}   0 0"/>
      <axis xyz="0 0 1"/>
      <limit lower="${-120 * PI / 180}" upper="${120 * PI / 180}"
             effort="${max_effort}" velocity="${max_velocity}" />
       <safety_controller soft_lower_limit="${-118 * PI / 180}"
           soft_upper_limit="${118 * PI / 180}"
           k_position="${safety_controller_k_pos}"
           k_velocity="${safety_controller_k_vel}"/>
      <dynamics damping="${d1}" friction="${f1}"/>
    </joint>

    <link name="link_2">
      <inertial>
        <origin xyz="0.007671 0.166693 0.003551" rpy="0 0 0"/>
        <mass value="4.502752"/>
        <inertia ixx="0.000318"  ixy="0"  ixz="0" iyy="0.018" iyz="0" izz="0.000419" />
      </inertial>

      <visual>
        <origin xyz="0 0 0" rpy="0 0 0"/>
        <geometry>
          <mesh filename="package://iiwa_description/meshes/iiwa14/visual/link_2.stl"/>
        </geometry>
        <material name="Orange"/>
      </visual>

      <collision>
        <origin xyz="0 0 0" rpy="0 0 0"/>
        <geometry>
          <mesh filename="package://iiwa_description/meshes/iiwa14/collision/link_2.stl"/>
        </geometry>
        <material name="Orange"/>
      </collision>
    </link>

    <!-- joint between link_2 and link_3 -->
    <joint name="joint_2" type="revolute">
      <parent link="link_2"/>
      <child link="link_3"/>
      <origin xyz="0 0.2045 0" rpy="${PI / 2} ${PI} ${PI}"/>
      <axis xyz="0 0 1"/>
      <limit lower="${-170 * PI / 180}" upper="${170 * PI / 180}"
             effort="${max_effort}" velocity="${max_velocity}" />
       <safety_controller soft_lower_limit="${-168 * PI / 180}"
           soft_upper_limit="${168 * PI / 180}"
           k_position="${safety_controller_k_pos}"
           k_velocity="${safety_controller_k_vel}"/>
      <dynamics damping="${d2}" friction="${f2}"/>
    </joint>

    <link name="link_3">
      <inertial>
        <origin xyz="-0.002246 -0.034918 ${-0.026522+0.2155}" rpy="0 0 0"/>
        <mass value="2.455197"/>
        <inertia ixx="0.002233"  ixy="-0.000046"  ixz="0" iyy="0.002191" iyz="0" izz="0.000725" />
      </inertial>

      <visual>
        <origin xyz="0 0 0" rpy="0 0 ${PI}"/>
        <geometry>
          <mesh filename="package://iiwa_description/meshes/iiwa14/visual/link_3.stl"/>
        </geometry>
        <material name="Orange"/>
      </visual>

      <collision>
        <origin xyz="0 0 0" rpy="0 0 ${PI}"/>
        <geometry>
          <mesh filename="package://iiwa_description/meshes/iiwa14/collision/link_3.stl"/>
        </geometry>
        <material name="Orange"/>
      </collision>
    </link>

   <!-- joint between link_3 and link_4 -->
    <joint name="joint_3" type="revolute">
      <parent link="link_3"/>
      <child link="link_4"/>
      <origin xyz="0 0 0.2155" rpy="${-PI / 2} 0 0"/>
      <axis xyz="0 0 1"/>
      <limit lower="${-120 * PI / 180}" upper="${120 * PI / 180}"
             effort="${max_effort}" velocity="${max_velocity}" />
       <safety_controller soft_lower_limit="${-118 * PI / 180}"
           soft_upper_limit="${118 * PI / 180}"
           k_position="${safety_controller_k_pos}"
           k_velocity="${safety_controller_k_vel}"/>
      <dynamics damping="${d3}" friction="${f3}"/>
    </joint>

    <link name="link_4">
      <inertial>
        <origin xyz="0.000196 -0.052679 0.038182" rpy="0 0 0"/>
        <mass value="2.611550"/>
        <inertia ixx="0.038444"  ixy="0.000880"  ixz="-0.001120" iyy="0.011437" iyz="-0.001113" izz="0.049880" />
      </inertial>

      <visual>
        <origin xyz="0 0 0" rpy="0 0 ${PI}"/>
        <geometry>
          <mesh filename="package://iiwa_description/meshes/iiwa14/visual/link_4.stl"/>
        </geometry>
        <material name="Orange"/>
      </visual>

      <collision>
        <origin xyz="0 0 0" rpy="0 0 ${PI}"/>
        <geometry>
          <mesh filename="package://iiwa_description/meshes/iiwa14/collision/link_4.stl"/>
        </geometry>
        <material name="Orange"/>
      </collision>
    </link>

    <!-- joint between link_4 and link_5 -->
    <joint name="joint_4" type="revolute">
      <parent link="link_4"/>
      <child link="link_5"/>
      <origin xyz="0 -0.1845 0" rpy="${PI / 2} 0 0"/>
      <axis xyz="0 0 1"/>
      <limit lower="${-170 * PI / 180}" upper="${170 * PI / 180}"
             effort="${max_effort}" velocity="${max_velocity}" />
       <safety_controller soft_lower_limit="${-168 * PI / 180}"
           soft_upper_limit="${168 * PI / 180}"
           k_position="${safety_controller_k_pos}"
           k_velocity="${safety_controller_k_vel}"/>
      <dynamics damping="${d4}" friction="${f4}"/>
    </joint>

    <link name="link_5">
      <inertial>
        <origin xyz="0.000054 -0.002367 ${-0.211336+0.2155}" rpy="0 0 0"/>
        <mass value="3.410009"/>
        <inertia ixx="0.002769"  ixy="0"  ixz="0" iyy="0.002842" iyz="0" izz="0.000117" />
      </inertial>

      <visual>
        <origin xyz="0 0 0" rpy="0 0 0"/>
        <geometry>
          <mesh filename="package://iiwa_description/meshes/iiwa14/visual/link_5.stl"/>
        </geometry>
        <material name="Orange"/>
      </visual>

      <collision>
        <origin xyz="0 0 0" rpy="0 0 0"/>
        <geometry>
          <mesh filename="package://iiwa_description/meshes/iiwa14/collision/link_5.stl"/>
        </geometry>
        <material name="Orange"/>
      </collision>
    </link>

 <!-- joint between link_5 and link_6 -->
    <joint name="joint_5" type="revolute">
      <parent link="link_5"/>
      <child link="link_6"/>
      <origin xyz="0 0 0.2155" rpy="${PI / 2} 0 0"/>
      <axis xyz="0 0 1"/>
      <limit lower="${-120 * PI / 180}" upper="${120 * PI / 180}"
             effort="${max_effort}" velocity="${max_velocity}" />
       <safety_controller soft_lower_limit="${-118 * PI / 180}"
           soft_upper_limit="${118 * PI / 180}"
           k_position="${safety_controller_k_pos}"
           k_velocity="${safety_controller_k_vel}"/>
      <dynamics damping="${d5}" friction="${f5}"/>
    </joint>

    <link name="link_6">
      <inertial>
        <origin xyz="0.000492 0.020190 -0.027496" rpy="0 0 0"/>
        <mass value="3.387949"/>
        <inertia ixx="0.000500"  ixy="0"  ixz="0" iyy="0.002809" iyz="0" izz="0.002315" />
      </inertial>

      <visual>
        <origin xyz="0 0 0" rpy="0 0 0"/>
        <geometry>
          <mesh filename="package://iiwa_description/meshes/iiwa14/visual/link_6.stl"/>
        </geometry>
        <material name="Orange"/>
      </visual>

      <collision>
        <origin xyz="0 0 0" rpy="0 0 0"/>
        <geometry>
          <mesh filename="package://iiwa_description/meshes/iiwa14/collision/link_6.stl"/>
        </geometry>
        <material name="Orange"/>
      </collision>
    </link>

 <!-- joint between link_6 and link_7 -->
    <joint name="joint_6" type="revolute">
      <parent link="link_6"/>
      <child link="link_7"/>
      <origin xyz="0 0.081 0" rpy="${- PI / 2} 0 0"/>
      <axis xyz="0 0 1"/>
      <limit lower="${-175 * PI / 180}" upper="${175 * PI / 180}"
             effort="${max_effort}" velocity="${max_velocity}" />
       <safety_controller soft_lower_limit="${-173 * PI / 180}"
           soft_upper_limit="${173 * PI / 180}"
           k_position="${safety_controller_k_pos}"
           k_velocity="${safety_controller_k_vel}"/>
      <dynamics damping="${d6}" friction="${f6}"/>
    </joint>

    <link name="link_7">
      <inertial>
        <origin xyz="-0.03465 -0.023242 ${0.071377-0.081}" rpy="0 0 0"/>
        <mass value="${0.354321 / 0.308 * 0.44}"/> <!--this is for the MFT Pneumatisch flange-->
        <inertia ixx="0.007946"  ixy="0.000221"  ixz="0.000294" iyy="0.010889" iyz="-0.000294" izz="0.002944" />
      </inertial>

      <visual>
        <origin xyz="0 0 0" rpy="0 0 0"/>
        <geometry>
          <mesh filename="package://iiwa_description/meshes/iiwa14/visual/link_7.stl"/>
        </geometry>
        <material name="Grey"/>
      </visual>

      <collision>
        <origin xyz="0 0 0" rpy="0 0 0"/>
        <geometry>
          <mesh filename="package://iiwa_description/meshes/iiwa14/collision/link_7.stl"/>
        </geometry>
        <material name="Grey"/>
      </collision>
    </link>

    <joint name="joint_ee" type="fixed">
      <parent link="link_7"/>
      <child link="link_ee"/>
      <origin xyz="0 0 0.045" rpy="0 -${PI/2} 0"/>
    </joint>

    <link name="link_ee">
    </link>

    <joint name="joint_ee_kuka" type="fixed">
      <parent link="link_7"/>
      <child link="link_ee_kuka"/>
      <origin xyz="0 0 0.045" rpy="${PI} ${PI} ${PI}"/>
      <axis xyz="0 0 1"/>
    </joint>

    <link name="link_ee_kuka">
    </link>

    <!--Extensions -->
    <xacro:iiwa_gazebo robot_name="${robot_name}" />
    <xacro:iiwa_transmission hardware_interface="${hardware_interface}"/>

  </xacro:macro>

</robot>
